Workbook

Sheet Survey Progress
A1: Summary
B2: Total Surveys Submitted | C2: Total Surveys Attempted | D2: # Eligible | E2: Average Duration (min)
A3: Screening & HHH | B3: =IFERROR(__xludf.DUMMYFUNCTION("COUNTA(IMPORTRANGE($B$32, ""data!E2:E800""))"),799.0) -> 799 | C3: =B3 -> 799 | D3: =IFERROR(__xludf.DUMMYFUNCTION("COUNTIF(IMPORTRANGE($B$32, ""data!P2:P800""), ""=1"")"),0.0) -> 0 | E3: =IFERROR(__xludf.DUMMYFUNCTION("AVERAGE(IMPORTRANGE($B32, ""Q:Q""))/60"),"#DIV/0!") -> #DIV/0!
A4: PM | B4: =IFERROR(__xludf.DUMMYFUNCTION("COUNTA(IMPORTRANGE($B$33, ""data!E2:E800""))"),799.0) -> 799 | C4: =B4 -> 799 | D4: =IFERROR(__xludf.DUMMYFUNCTION("COUNTIFS(IMPORTRANGE($B$33, ""data!K2:K800""), ""=1"")"),0.0) -> 0 | E4: =IFERROR(__xludf.DUMMYFUNCTION("AVERAGE(IMPORTRANGE($B33, ""M:M""))/60"),"#DIV/0!") -> #DIV/0!
A5: Woman | B5: =IFERROR(__xludf.DUMMYFUNCTION("COUNTA(IMPORTRANGE($B$34, ""data!E2:E800""))"),799.0) -> 799 | C5: =B5 -> 799 | D5: =IFERROR(__xludf.DUMMYFUNCTION("COUNTIF(IMPORTRANGE($B$34, ""data!K2:K800""), ""=1"")"),0.0) -> 0 | E5: =IFERROR(__xludf.DUMMYFUNCTION("AVERAGE(IMPORTRANGE($B34, ""M:M""))/60"),"#DIV/0!") -> #DIV/0!
A7: Summary By Day: Completed
A9: Screening & HHH | B9: =IFERROR(__xludf.DUMMYFUNCTION("COUNTIF(IMPORTRANGE($B$32, ""data!S2:S800""), ""*""&B$8&""*"")"),0.0) -> 0 | C9: =IFERROR(__xludf.DUMMYFUNCTION("COUNTIF(IMPORTRANGE($B$32, ""data!S2:S800""), ""*""&C$8&""*"")"),0.0) -> 0 | D9: =IFERROR(__xludf.DUMMYFUNCTION("COUNTIF(IMPORTRANGE($B$32, ""data!S2:S800""), ""*""&D$8&""*"")"),0.0) -> 0 | E9: =IFERROR(__xludf.DUMMYFUNCTION("COUNTIF(IMPORTRANGE($B$32, ""data!S2:S800""), ""*""&E$8&""*"")"),0.0) -> 0 | F9: =IFERROR(__xludf.DUMMYFUNCTION("COUNTIF(IMPORTRANGE($B$32, ""data!S2:S800""), ""*""&F$8&""*"")"),0.0) -> 0 | G9: =IFERROR(__xludf.DUMMYFUNCTION("COUNTIF(IMPORTRANGE($B$32, ""data!S2:S800""), ""*""&G$8&""*"")"),0.0) -> 0 | H9: =IFERROR(__xludf.DUMMYFUNCTION("COUNTIF(IMPORTRANGE($B$32, ""data!S2:S800""), ""*""&H$8&""*"")"),0.0) -> 0 | I9: =IFERROR(__xludf.DUMMYFUNCTION("COUNTIF(IMPORTRANGE($B$32, ""data!S2:S800""), ""*""&I$8&""*"")"),0.0) -> 0 | J9: =IFERROR(__xludf.DUMMYFUNCTION("COUNTIF(IMPORTRANGE($B$32, ""data!S2:S800""), ""*""&J$8&""*"")"),0.0) -> 0 | K9: =IFERROR(__xludf.DUMMYFUNCTION("COUNTIF(IMPORTRANGE($B$32, ""data!S2:S800""), ""*""&K$8&""*"")"),0.0) -> 0 | L9: =IFERROR(__xludf.DUMMYFUNCTION("COUNTIF(IMPORTRANGE($B$32, ""data!S2:S800""), ""*""&L$8&""*"")"),0.0) -> 0 | M9: =IFERROR(__xludf.DUMMYFUNCTION("COUNTIF(IMPORTRANGE($B$32, ""data!S2:S800""), ""*""&M$8&""*"")"),0.0) -> 0 | N9: =IFERROR(__xludf.DUMMYFUNCTION("COUNTIF(IMPORTRANGE($B$32, ""data!S2:S800""), ""*""&N$8&""*"")"),0.0) -> 0 | O9: =IFERROR(__xludf.DUMMYFUNCTION("COUNTIF(IMPORTRANGE($B$32, ""data!S2:S800""), ""*""&O$8&""*"")"),0.0) -> 0 | P9: =IFERROR(__xludf.DUMMYFUNCTION("COUNTIF(IMPORTRANGE($B$32, ""data!S2:S800""), ""*""&P$8&""*"")"),0.0) -> 0 | Q9: =IFERROR(__xludf.DUMMYFUNCTION("COUNTIF(IMPORTRANGE($B$32, ""data!S2:S800""), ""*""&Q$8&""*"")"),0.0) -> 0
A10: PM | B10: =IFERROR(__xludf.DUMMYFUNCTION("COUNTIF(IMPORTRANGE($B$33, ""data!O2:O800""), ""*""&B$8&""*"")"),0.0) -> 0 | C10: =IFERROR(__xludf.DUMMYFUNCTION("COUNTIF(IMPORTRANGE($B$33, ""data!O2:O800""), ""*""&C$8&""*"")"),0.0) -> 0 | D10: =IFERROR(__xludf.DUMMYFUNCTION("COUNTIF(IMPORTRANGE($B$33, ""data!O2:O800""), ""*""&D$8&""*"")"),0.0) -> 0 | E10: =IFERROR(__xludf.DUMMYFUNCTION("COUNTIF(IMPORTRANGE($B$33, ""data!O2:O800""), ""*""&E$8&""*"")"),0.0) -> 0 | F10: =IFERROR(__xludf.DUMMYFUNCTION("COUNTIF(IMPORTRANGE($B$33, ""data!O2:O800""), ""*""&F$8&""*"")"),0.0) -> 0 | G10: =IFERROR(__xludf.DUMMYFUNCTION("COUNTIF(IMPORTRANGE($B$33, ""data!O2:O800""), ""*""&G$8&""*"")"),0.0) -> 0 | H10: =IFERROR(__xludf.DUMMYFUNCTION("COUNTIF(IMPORTRANGE($B$33, ""data!O2:O800""), ""*""&H$8&""*"")"),0.0) -> 0 | I10: =IFERROR(__xludf.DUMMYFUNCTION("COUNTIF(IMPORTRANGE($B$33, ""data!O2:O800""), ""*""&I$8&""*"")"),0.0) -> 0 | J10: =IFERROR(__xludf.DUMMYFUNCTION("COUNTIF(IMPORTRANGE($B$33, ""data!O2:O800""), ""*""&J$8&""*"")"),0.0) -> 0 | K10: =IFERROR(__xludf.DUMMYFUNCTION("COUNTIF(IMPORTRANGE($B$33, ""data!O2:O800""), ""*""&K$8&""*"")"),0.0) -> 0 | L10: =IFERROR(__xludf.DUMMYFUNCTION("COUNTIF(IMPORTRANGE($B$33, ""data!O2:O800""), ""*""&L$8&""*"")"),0.0) -> 0 | M10: =IFERROR(__xludf.DUMMYFUNCTION("COUNTIF(IMPORTRANGE($B$33, ""data!O2:O800""), ""*""&M$8&""*"")"),0.0) -> 0 | N10: =IFERROR(__xludf.DUMMYFUNCTION("COUNTIF(IMPORTRANGE($B$33, ""data!O2:O800""), ""*""&N$8&""*"")"),0.0) -> 0 | O10: =IFERROR(__xludf.DUMMYFUNCTION("COUNTIF(IMPORTRANGE($B$33, ""data!O2:O800""), ""*""&O$8&""*"")"),0.0) -> 0 | P10: =IFERROR(__xludf.DUMMYFUNCTION("COUNTIF(IMPORTRANGE($B$33, ""data!O2:O800""), ""*""&P$8&""*"")"),0.0) -> 0 | Q10: =IFERROR(__xludf.DUMMYFUNCTION("COUNTIF(IMPORTRANGE($B$33, ""data!O2:O800""), ""*""&Q$8&""*"")"),0.0) -> 0
A11: Woman | B11: =IFERROR(__xludf.DUMMYFUNCTION("COUNTIF(IMPORTRANGE($B$34, ""data!O2:O800""), ""*""&B$8&""*"")"),0.0) -> 0 | C11: =IFERROR(__xludf.DUMMYFUNCTION("COUNTIF(IMPORTRANGE($B$34, ""data!O2:O800""), ""*""&C$8&""*"")"),0.0) -> 0 | D11: =IFERROR(__xludf.DUMMYFUNCTION("COUNTIF(IMPORTRANGE($B$34, ""data!O2:O800""), ""*""&D$8&""*"")"),0.0) -> 0 | E11: =IFERROR(__xludf.DUMMYFUNCTION("COUNTIF(IMPORTRANGE($B$34, ""data!O2:O800""), ""*""&E$8&""*"")"),0.0) -> 0 | F11: =IFERROR(__xludf.DUMMYFUNCTION("COUNTIF(IMPORTRANGE($B$34, ""data!O2:O800""), ""*""&F$8&""*"")"),0.0) -> 0 | G11: =IFERROR(__xludf.DUMMYFUNCTION("COUNTIF(IMPORTRANGE($B$34, ""data!O2:O800""), ""*""&G$8&""*"")"),0.0) -> 0 | H11: =IFERROR(__xludf.DUMMYFUNCTION("COUNTIF(IMPORTRANGE($B$34, ""data!O2:O800""), ""*""&H$8&""*"")"),0.0) -> 0 | I11: =IFERROR(__xludf.DUMMYFUNCTION("COUNTIF(IMPORTRANGE($B$34, ""data!O2:O800""), ""*""&I$8&""*"")"),0.0) -> 0 | J11: =IFERROR(__xludf.DUMMYFUNCTION("COUNTIF(IMPORTRANGE($B$34, ""data!O2:O800""), ""*""&J$8&""*"")"),0.0) -> 0 | K11: =IFERROR(__xludf.DUMMYFUNCTION("COUNTIF(IMPORTRANGE($B$34, ""data!O2:O800""), ""*""&K$8&""*"")"),0.0) -> 0 | L11: =IFERROR(__xludf.DUMMYFUNCTION("COUNTIF(IMPORTRANGE($B$34, ""data!O2:O800""), ""*""&L$8&""*"")"),0.0) -> 0 | M11: =IFERROR(__xludf.DUMMYFUNCTION("COUNTIF(IMPORTRANGE($B$34, ""data!O2:O800""), ""*""&M$8&""*"")"),0.0) -> 0 | N11: =IFERROR(__xludf.DUMMYFUNCTION("COUNTIF(IMPORTRANGE($B$34, ""data!O2:O800""), ""*""&N$8&""*"")"),0.0) -> 0 | O11: =IFERROR(__xludf.DUMMYFUNCTION("COUNTIF(IMPORTRANGE($B$34, ""data!O2:O800""), ""*""&O$8&""*"")"),0.0) -> 0 | P11: =IFERROR(__xludf.DUMMYFUNCTION("COUNTIF(IMPORTRANGE($B$34, ""data!O2:O800""), ""*""&P$8&""*"")"),0.0) -> 0 | Q11: =IFERROR(__xludf.DUMMYFUNCTION("COUNTIF(IMPORTRANGE($B$34, ""data!O2:O800""), ""*""&Q$8&""*"")"),0.0) -> 0
A12: Total | B12: =SUM(B9:B11) -> 0 | C12: =SUM(C9:C11) -> 0 | D12: =SUM(D9:D11) -> 0 | E12: =SUM(E9:E11) -> 0 | F12: =SUM(F9:F11) -> 0 | G12: =SUM(G9:G11) -> 0 | H12: =SUM(H9:H11) -> 0 | I12: =SUM(I9:I11) -> 0 | ... Q12: =SUM(Q9:Q11) -> 0
A14: Summary by Area
A16: Screening & HHH | B16: =IFERROR(__xludf.DUMMYFUNCTION("COUNTIF(IMPORTRANGE($B32, ""data!G2:G800""), ""1"")"),788.0) -> 788 | C16: =IFERROR(__xludf.DUMMYFUNCTION("COUNTIF(IMPORTRANGE($B32, ""data!G2:G800""), ""2"")"),0.0) -> 0 | D16: =IFERROR(__xludf.DUMMYFUNCTION("COUNTIF(IMPORTRANGE($B32, ""data!G2:G800""), ""3"")"),0.0) -> 0 | E16: =IFERROR(__xludf.DUMMYFUNCTION("COUNTIF(IMPORTRANGE($B32, ""data!G2:G800""), ""4"")"),0.0) -> 0 | F16: =IFERROR(__xludf.DUMMYFUNCTION("COUNTIF(IMPORTRANGE($B32, ""data!G2:G800""), ""5"")"),0.0) -> 0 | G16: =IFERROR(__xludf.DUMMYFUNCTION("COUNTIF(IMPORTRANGE($B32, ""data!G2:G800""), ""6"")"),0.0) -> 0 | H16: =IFERROR(__xludf.DUMMYFUNCTION("COUNTIF(IMPORTRANGE($B32, ""data!G2:G800""), ""7"")"),0.0) -> 0 | I16: =IFERROR(__xludf.DUMMYFUNCTION("COUNTIF(IMPORTRANGE($B32, ""data!G2:G800""), ""8"")"),0.0) -> 0
A17: PM | B17: =IFERROR(__xludf.DUMMYFUNCTION("COUNTIF(IMPORTRANGE($B33, ""data!G2:G800""), ""1"")"),799.0) -> 799 | C17: =IFERROR(__xludf.DUMMYFUNCTION("COUNTIF(IMPORTRANGE($B33, ""data!G2:G800""), ""2"")"),0.0) -> 0 | D17: =IFERROR(__xludf.DUMMYFUNCTION("COUNTIF(IMPORTRANGE($B33, ""data!G2:G800""), ""3"")"),0.0) -> 0 | E17: =IFERROR(__xludf.DUMMYFUNCTION("COUNTIF(IMPORTRANGE($B33, ""data!G2:G800""), ""4"")"),0.0) -> 0 | F17: =IFERROR(__xludf.DUMMYFUNCTION("COUNTIF(IMPORTRANGE($B33, ""data!G2:G800""), ""5"")"),0.0) -> 0 | G17: =IFERROR(__xludf.DUMMYFUNCTION("COUNTIF(IMPORTRANGE($B33, ""data!G2:G800""), ""6"")"),0.0) -> 0 | H17: =IFERROR(__xludf.DUMMYFUNCTION("COUNTIF(IMPORTRANGE($B33, ""data!G2:G800""), ""7"")"),0.0) -> 0 | I17: =IFERROR(__xludf.DUMMYFUNCTION("COUNTIF(IMPORTRANGE($B33, ""data!G2:G800""), ""8"")"),0.0) -> 0
A18: Woman | B18: =IFERROR(__xludf.DUMMYFUNCTION("COUNTIF(IMPORTRANGE($B34, ""data!G2:G800""), ""1"")"),0.0) -> 0 | C18: =IFERROR(__xludf.DUMMYFUNCTION("COUNTIF(IMPORTRANGE($B34, ""data!G2:G800""), ""2"")"),0.0) -> 0 | D18: =IFERROR(__xludf.DUMMYFUNCTION("COUNTIF(IMPORTRANGE($B34, ""data!G2:G800""), ""3"")"),0.0) -> 0 | E18: =IFERROR(__xludf.DUMMYFUNCTION("COUNTIF(IMPORTRANGE($B34, ""data!G2:G800""), ""4"")"),0.0) -> 0 | F18: =IFERROR(__xludf.DUMMYFUNCTION("COUNTIF(IMPORTRANGE($B34, ""data!G2:G800""), ""5"")"),0.0) -> 0 | G18: =IFERROR(__xludf.DUMMYFUNCTION("COUNTIF(IMPORTRANGE($B34, ""data!G2:G800""), ""6"")"),0.0) -> 0 | H18: =IFERROR(__xludf.DUMMYFUNCTION("COUNTIF(IMPORTRANGE($B34, ""data!G2:G800""), ""7"")"),0.0) -> 0 | I18: =IFERROR(__xludf.DUMMYFUNCTION("COUNTIF(IMPORTRANGE($B34, ""data!G2:G800""), ""8"")"),0.0) -> 0
A19: Total | B19: =SUM(B16:B18) -> 1587 | C19: =SUM(C16:C18) -> 0 | D19: =SUM(D16:D18) -> 0 | E19: =SUM(E16:E18) -> 0 | F19: =SUM(F16:F18) -> 0 | G19: =SUM(G16:G18) -> 0 | H19: =SUM(H16:H18) -> 0 | I19: =SUM(I16:I18) -> 0
A32: Screening | B32: https://docs.google.com/spreadsheets/d/1tU4Qo2DtF9Xe5S6gIoKHsRfFV726hJmY9lYRofmirHo/edit#gid=1181262859
A33: PM | B33: https://docs.google.com/spreadsheets/d/1fFfESj3oIQjwk2c8HB-TSt4vyYGbHLlIzmuzmUq6cT0/edit?usp=sharing
A34: Woman | B34: https://docs.google.com/spreadsheets/d/1l38eTowlS5apPQYieM_wB7W_mVwZRvoVp75QAurEFbw/edit?usp=sharing
A35: SHM | B35: https://docs.google.com/spreadsheets/d/1vLOhdr9eYys_lGrQi_ovg7Sm2aCQ0dqPoIjaEOBAc3k/edit?usp=sharing

Sheet IDs
A1: =CONCAT("Completed households: ", COUNTIF(E6:E500, "=1")) -> Completed households: 0
A2: =CONCAT("Incomplete eligible households: ", COUNTIFS(E6:E500, "=0", A6:A500, "<>"&"")) -> Incomplete eligible households: 1
A3: =CONCAT("Ineligible households: ", COUNTIF(B6:B205, "Ineligible")) -> Ineligible households: 0
A5: IDs | B5: Screening | C5: PM | D5: Woman
A6: =IFERROR(__xludf.DUMMYFUNCTION("UNIQUE(IMPORTRANGE('Survey Progress'!$B$32, ""data!H2:H800""))"),0.0) -> 0 | B6: =IFERROR(__xludf.DUMMYFUNCTION("IF(ISERROR(VLOOKUP(A6, IMPORTRANGE('Survey Progress'!$B$32, ""data!H2:M800""), 5, FALSE)), """", IF(VLOOKUP(A6, IMPORTRANGE('Survey Progress'!$B$32, ""data!H2:M800""), 5, FALSE) = 1, ""Eligible"", ""Ineligible""))"),"Eligible") -> Eligible | C6: =IFERROR(__xludf.DUMMYFUNCTION("IF(A6="""", """", IF(ISERROR(VLOOKUP(A6, IMPORTRANGE('Survey Progress'!$B$33, ""data!I2:L800""), 1, FALSE)), ""No Survey"", IF(VLOOKUP(A6, IMPORTRANGE('Survey Progress'!$B$33, ""data!I2:L800""), 2, FALSE) = 0, ""Incomplete"", ""Complete"")))"),"No Survey") -> No Survey | D6: =IFERROR(__xludf.DUMMYFUNCTION("IF(A6="""", """", IF(ISERROR(VLOOKUP(A6, IMPORTRANGE('Survey Progress'!$B$34, ""data!I2:L800""), 1, FALSE)), ""No Survey"", IF(VLOOKUP(A6, IMPORTRANGE('Survey Progress'!$B$34, ""data!I2:L800""), 2, FALSE) = 0, ""Incomplete"", ""Complete"")))"),"Complete") -> Complete | E6: =IF(B6="Ineligible", 2, IF(AND(C6="Complete", D6="Complete"), 1, 0)) -> 0
B7: =IFERROR(__xludf.DUMMYFUNCTION("IF(ISERROR(VLOOKUP(A7, IMPORTRANGE('Survey Progress'!$B$32, ""data!H2:M800""), 5, FALSE)), """", IF(VLOOKUP(A7, IMPORTRANGE('Survey Progress'!$B$32, ""data!H2:M800""), 5, FALSE) = 1, ""Eligible"", ""Ineligible""))"),"Eligible") -> Eligible | C7: =IFERROR(__xludf.DUMMYFUNCTION("IF(A7="""", """", IF(ISERROR(VLOOKUP(A7, IMPORTRANGE('Survey Progress'!$B$33, ""data!I2:L800""), 1, FALSE)), ""No Survey"", IF(VLOOKUP(A7, IMPORTRANGE('Survey Progress'!$B$33, ""data!I2:L800""), 2, FALSE) = 0, ""Incomplete"", ""Complete"")))"),"") | D7: =IFERROR(__xludf.DUMMYFUNCTION("IF(A7="""", """", IF(ISERROR(VLOOKUP(A7, IMPORTRANGE('Survey Progress'!$B$34, ""data!I2:L800""), 1, FALSE)), ""No Survey"", IF(VLOOKUP(A7, IMPORTRANGE('Survey Progress'!$B$34, ""data!I2:L800""), 2, FALSE) = 0, ""Incomplete"", ""Complete"")))"),"") | E7: =IF(B7="Ineligible", 2, IF(AND(C7="Complete", D7="Complete"), 1, 0)) -> 0 | H7: GRAY = Ineligible HH
B8: =IFERROR(__xludf.DUMMYFUNCTION("IF(ISERROR(VLOOKUP(A8, IMPORTRANGE('Survey Progress'!$B$32, ""data!H2:M800""), 5, FALSE)), """", IF(VLOOKUP(A8, IMPORTRANGE('Survey Progress'!$B$32, ""data!H2:M800""), 5, FALSE) = 1, ""Eligible"", ""Ineligible""))"),"Eligible") -> Eligible | C8: =IFERROR(__xludf.DUMMYFUNCTION("IF(A8="""", """", IF(ISERROR(VLOOKUP(A8, IMPORTRANGE('Survey Progress'!$B$33, ""data!I2:L800""), 1, FALSE)), ""No Survey"", IF(VLOOKUP(A8, IMPORTRANGE('Survey Progress'!$B$33, ""data!I2:L800""), 2, FALSE) = 0, ""Incomplete"", ""Complete"")))"),"") | D8: =IFERROR(__xludf.DUMMYFUNCTION("IF(A8="""", """", IF(ISERROR(VLOOKUP(A8, IMPORTRANGE('Survey Progress'!$B$34, ""data!I2:L800""), 1, FALSE)), ""No Survey"", IF(VLOOKUP(A8, IMPORTRANGE('Survey Progress'!$B$34, ""data!I2:L800""), 2, FALSE) = 0, ""Incomplete"", ""Complete"")))"),"") | E8: =IF(B8="Ineligible", 2, IF(AND(C8="Complete", D8="Complete"), 1, 0)) -> 0 | H8: GREEN = Eligible HH & PM, ALL Surveys complete
B9: =IFERROR(__xludf.DUMMYFUNCTION("IF(ISERROR(VLOOKUP(A9, IMPORTRANGE('Survey Progress'!$B$32, ""data!H2:M800""), 5, FALSE)), """", IF(VLOOKUP(A9, IMPORTRANGE('Survey Progress'!$B$32, ""data!H2:M800""), 5, FALSE) = 1, ""Eligible"", ""Ineligible""))"),"Eligible") -> Eligible | C9: =IFERROR(__xludf.DUMMYFUNCTION("IF(A9="""", """", IF(ISERROR(VLOOKUP(A9, IMPORTRANGE('Survey Progress'!$B$33, ""data!I2:L800""), 1, FALSE)), ""No Survey"", IF(VLOOKUP(A9, IMPORTRANGE('Survey Progress'!$B$33, ""data!I2:L800""), 2, FALSE) = 0, ""Incomplete"", ""Complete"")))"),"") | D9: =IFERROR(__xludf.DUMMYFUNCTION("IF(A9="""", """", IF(ISERROR(VLOOKUP(A9, IMPORTRANGE('Survey Progress'!$B$34, ""data!I2:L800""), 1, FALSE)), ""No Survey"", IF(VLOOKUP(A9, IMPORTRANGE('Survey Progress'!$B$34, ""data!I2:L800""), 2, FALSE) = 0, ""Incomplete"", ""Complete"")))"),"") | E9: =IF(B9="Ineligible", 2, IF(AND(C9="Complete", D9="Complete"), 1, 0)) -> 0 | H9: RED = Eligible HH & PM, Some surveys incomplete
B10: =IFERROR(__xludf.DUMMYFUNCTION("IF(ISERROR(VLOOKUP(A10, IMPORTRANGE('Survey Progress'!$B$32, ""data!H2:M800""), 5, FALSE)), """", IF(VLOOKUP(A10, IMPORTRANGE('Survey Progress'!$B$32, ""data!H2:M800""), 5, FALSE) = 1, ""Eligible"", ""Ineligible""))"),"Eligible") -> Eligible | C10: =IFERROR(__xludf.DUMMYFUNCTION("IF(A10="""", """", IF(ISERROR(VLOOKUP(A10, IMPORTRANGE('Survey Progress'!$B$33, ""data!I2:L800""), 1, FALSE)), ""No Survey"", IF(VLOOKUP(A10, IMPORTRANGE('Survey Progress'!$B$33, ""data!I2:L800""), 2, FALSE) = 0, ""Incomplete"", ""Complete"")))"),"") | D10: =IFERROR(__xludf.DUMMYFUNCTION("IF(A10="""", """", IF(ISERROR(VLOOKUP(A10, IMPORTRANGE('Survey Progress'!$B$34, ""data!I2:L800""), 1, FALSE)), ""No Survey"", IF(VLOOKUP(A10, IMPORTRANGE('Survey Progress'!$B$34, ""data!I2:L800""), 2, FALSE) = 0, ""Incomplete"", ""Complete"")))"),"") | E10: =IF(B10="Ineligible", 2, IF(AND(C10="Complete", D10="Complete"), 1, 0)) -> 0
B11: =IFERROR(__xludf.DUMMYFUNCTION("IF(ISERROR(VLOOKUP(A11, IMPORTRANGE('Survey Progress'!$B$32, ""data!H2:M800""), 5, FALSE)), """", IF(VLOOKUP(A11, IMPORTRANGE('Survey Progress'!$B$32, ""data!H2:M800""), 5, FALSE) = 1, ""Eligible"", ""Ineligible""))"),"Eligible") -> Eligible | C11: =IFERROR(__xludf.DUMMYFUNCTION("IF(A11="""", """", IF(ISERROR(VLOOKUP(A11, IMPORTRANGE('Survey Progress'!$B$33, ""data!I2:L800""), 1, FALSE)), ""No Survey"", IF(VLOOKUP(A11, IMPORTRANGE('Survey Progress'!$B$33, ""data!I2:L800""), 2, FALSE) = 0, ""Incomplete"", ""Complete"")))"),"") | D11: =IFERROR(__xludf.DUMMYFUNCTION("IF(A11="""", """", IF(ISERROR(VLOOKUP(A11, IMPORTRANGE('Survey Progress'!$B$34, ""data!I2:L800""), 1, FALSE)), ""No Survey"", IF(VLOOKUP(A11, IMPORTRANGE('Survey Progress'!$B$34, ""data!I2:L800""), 2, FALSE) = 0, ""Incomplete"", ""Complete"")))"),"") | E11: =IF(B11="Ineligible", 2, IF(AND(C11="Complete", D11="Complete"), 1, 0)) -> 0
B12: =IFERROR(__xludf.DUMMYFUNCTION("IF(ISERROR(VLOOKUP(A12, IMPORTRANGE('Survey Progress'!$B$32, ""data!H2:M800""), 5, FALSE)), """", IF(VLOOKUP(A12, IMPORTRANGE('Survey Progress'!$B$32, ""data!H2:M800""), 5, FALSE) = 1, ""Eligible"", ""Ineligible""))"),"Eligible") -> Eligible | C12: =IFERROR(__xludf.DUMMYFUNCTION("IF(A12="""", """", IF(ISERROR(VLOOKUP(A12, IMPORTRANGE('Survey Progress'!$B$33, ""data!I2:L800""), 1, FALSE)), ""No Survey"", IF(VLOOKUP(A12, IMPORTRANGE('Survey Progress'!$B$33, ""data!I2:L800""), 2, FALSE) = 0, ""Incomplete"", ""Complete"")))"),"") | D12: =IFERROR(__xludf.DUMMYFUNCTION("IF(A12="""", """", IF(ISERROR(VLOOKUP(A12, IMPORTRANGE('Survey Progress'!$B$34, ""data!I2:L800""), 1, FALSE)), ""No Survey"", IF(VLOOKUP(A12, IMPORTRANGE('Survey Progress'!$B$34, ""data!I2:L800""), 2, FALSE) = 0, ""Incomplete"", ""Complete"")))"),"") | E12: =IF(B12="Ineligible", 2, IF(AND(C12="Complete", D12="Complete"), 1, 0)) -> 0
B13: =IFERROR(__xludf.DUMMYFUNCTION("IF(ISERROR(VLOOKUP(A13, IMPORTRANGE('Survey Progress'!$B$32, ""data!H2:M800""), 5, FALSE)), """", IF(VLOOKUP(A13, IMPORTRANGE('Survey Progress'!$B$32, ""data!H2:M800""), 5, FALSE) = 1, ""Eligible"", ""Ineligible""))"),"Eligible") -> Eligible | C13: =IFERROR(__xludf.DUMMYFUNCTION("IF(A13="""", """", IF(ISERROR(VLOOKUP(A13, IMPORTRANGE('Survey Progress'!$B$33, ""data!I2:L800""), 1, FALSE)), ""No Survey"", IF(VLOOKUP(A13, IMPORTRANGE('Survey Progress'!$B$33, ""data!I2:L800""), 2, FALSE) = 0, ""Incomplete"", ""Complete"")))"),"") | D13: =IFERROR(__xludf.DUMMYFUNCTION("IF(A13="""", """", IF(ISERROR(VLOOKUP(A13, IMPORTRANGE('Survey Progress'!$B$34, ""data!I2:L800""), 1, FALSE)), ""No Survey"", IF(VLOOKUP(A13, IMPORTRANGE('Survey Progress'!$B$34, ""data!I2:L800""), 2, FALSE) = 0, ""Incomplete"", ""Complete"")))"),"") | E13: =IF(B13="Ineligible", 2, IF(AND(C13="Complete", D13="Complete"), 1, 0)) -> 0
B14: =IFERROR(__xludf.DUMMYFUNCTION("IF(ISERROR(VLOOKUP(A14, IMPORTRANGE('Survey Progress'!$B$32, ""data!H2:M800""), 5, FALSE)), """", IF(VLOOKUP(A14, IMPORTRANGE('Survey Progress'!$B$32, ""data!H2:M800""), 5, FALSE) = 1, ""Eligible"", ""Ineligible""))"),"Eligible") -> Eligible | C14: =IFERROR(__xludf.DUMMYFUNCTION("IF(A14="""", """", IF(ISERROR(VLOOKUP(A14, IMPORTRANGE('Survey Progress'!$B$33, ""data!I2:L800""), 1, FALSE)), ""No Survey"", IF(VLOOKUP(A14, IMPORTRANGE('Survey Progress'!$B$33, ""data!I2:L800""), 2, FALSE) = 0, ""Incomplete"", ""Complete"")))"),"") | D14: =IFERROR(__xludf.DUMMYFUNCTION("IF(A14="""", """", IF(ISERROR(VLOOKUP(A14, IMPORTRANGE('Survey Progress'!$B$34, ""data!I2:L800""), 1, FALSE)), ""No Survey"", IF(VLOOKUP(A14, IMPORTRANGE('Survey Progress'!$B$34, ""data!I2:L800""), 2, FALSE) = 0, ""Incomplete"", ""Complete"")))"),"") | E14: =IF(B14="Ineligible", 2, IF(AND(C14="Complete", D14="Complete"), 1, 0)) -> 0
B15: =IFERROR(__xludf.DUMMYFUNCTION("IF(ISERROR(VLOOKUP(A15, IMPORTRANGE('Survey Progress'!$B$32, ""data!H2:M800""), 5, FALSE)), """", IF(VLOOKUP(A15, IMPORTRANGE('Survey Progress'!$B$32, ""data!H2:M800""), 5, FALSE) = 1, ""Eligible"", ""Ineligible""))"),"Eligible") -> Eligible | C15: =IFERROR(__xludf.DUMMYFUNCTION("IF(A15="""", """", IF(ISERROR(VLOOKUP(A15, IMPORTRANGE('Survey Progress'!$B$33, ""data!I2:L800""), 1, FALSE)), ""No Survey"", IF(VLOOKUP(A15, IMPORTRANGE('Survey Progress'!$B$33, ""data!I2:L800""), 2, FALSE) = 0, ""Incomplete"", ""Complete"")))"),"") | D15: =IFERROR(__xludf.DUMMYFUNCTION("IF(A15="""", """", IF(ISERROR(VLOOKUP(A15, IMPORTRANGE('Survey Progress'!$B$34, ""data!I2:L800""), 1, FALSE)), ""No Survey"", IF(VLOOKUP(A15, IMPORTRANGE('Survey Progress'!$B$34, ""data!I2:L800""), 2, FALSE) = 0, ""Incomplete"", ""Complete"")))"),"") | E15: =IF(B15="Ineligible", 2, IF(AND(C15="Complete", D15="Complete"), 1, 0)) -> 0
B16: =IFERROR(__xludf.DUMMYFUNCTION("IF(ISERROR(VLOOKUP(A16, IMPORTRANGE('Survey Progress'!$B$32, ""data!H2:M800""), 5, FALSE)), """", IF(VLOOKUP(A16, IMPORTRANGE('Survey Progress'!$B$32, ""data!H2:M800""), 5, FALSE) = 1, ""Eligible"", ""Ineligible""))"),"Eligible") -> Eligible | C16: =IFERROR(__xludf.DUMMYFUNCTION("IF(A16="""", """", IF(ISERROR(VLOOKUP(A16, IMPORTRANGE('Survey Progress'!$B$33, ""data!I2:L800""), 1, FALSE)), ""No Survey"", IF(VLOOKUP(A16, IMPORTRANGE('Survey Progress'!$B$33, ""data!I2:L800""), 2, FALSE) = 0, ""Incomplete"", ""Complete"")))"),"") | D16: =IFERROR(__xludf.DUMMYFUNCTION("IF(A16="""", """", IF(ISERROR(VLOOKUP(A16, IMPORTRANGE('Survey Progress'!$B$34, ""data!I2:L800""), 1, FALSE)), ""No Survey"", IF(VLOOKUP(A16, IMPORTRANGE('Survey Progress'!$B$34, ""data!I2:L800""), 2, FALSE) = 0, ""Incomplete"", ""Complete"")))"),"") | E16: =IF(B16="Ineligible", 2, IF(AND(C16="Complete", D16="Complete"), 1, 0)) -> 0
B17: =IFERROR(__xludf.DUMMYFUNCTION("IF(ISERROR(VLOOKUP(A17, IMPORTRANGE('Survey Progress'!$B$32, ""data!H2:M800""), 5, FALSE)), """", IF(VLOOKUP(A17, IMPORTRANGE('Survey Progress'!$B$32, ""data!H2:M800""), 5, FALSE) = 1, ""Eligible"", ""Ineligible""))"),"Eligible") -> Eligible | C17: =IFERROR(__xludf.DUMMYFUNCTION("IF(A17="""", """", IF(ISERROR(VLOOKUP(A17, IMPORTRANGE('Survey Progress'!$B$33, ""data!I2:L800""), 1, FALSE)), ""No Survey"", IF(VLOOKUP(A17, IMPORTRANGE('Survey Progress'!$B$33, ""data!I2:L800""), 2, FALSE) = 0, ""Incomplete"", ""Complete"")))"),"") | D17: =IFERROR(__xludf.DUMMYFUNCTION("IF(A17="""", """", IF(ISERROR(VLOOKUP(A17, IMPORTRANGE('Survey Progress'!$B$34, ""data!I2:L800""), 1, FALSE)), ""No Survey"", IF(VLOOKUP(A17, IMPORTRANGE('Survey Progress'!$B$34, ""data!I2:L800""), 2, FALSE) = 0, ""Incomplete"", ""Complete"")))"),"") | E17: =IF(B17="Ineligible", 2, IF(AND(C17="Complete", D17="Complete"), 1, 0)) -> 0
B18: =IFERROR(__xludf.DUMMYFUNCTION("IF(ISERROR(VLOOKUP(A18, IMPORTRANGE('Survey Progress'!$B$32, ""data!H2:M800""), 5, FALSE)), """", IF(VLOOKUP(A18, IMPORTRANGE('Survey Progress'!$B$32, ""data!H2:M800""), 5, FALSE) = 1, ""Eligible"", ""Ineligible""))"),"Eligible") -> Eligible | C18: =IFERROR(__xludf.DUMMYFUNCTION("IF(A18="""", """", IF(ISERROR(VLOOKUP(A18, IMPORTRANGE('Survey Progress'!$B$33, ""data!I2:L800""), 1, FALSE)), ""No Survey"", IF(VLOOKUP(A18, IMPORTRANGE('Survey Progress'!$B$33, ""data!I2:L800""), 2, FALSE) = 0, ""Incomplete"", ""Complete"")))"),"") | D18: =IFERROR(__xludf.DUMMYFUNCTION("IF(A18="""", """", IF(ISERROR(VLOOKUP(A18, IMPORTRANGE('Survey Progress'!$B$34, ""data!I2:L800""), 1, FALSE)), ""No Survey"", IF(VLOOKUP(A18, IMPORTRANGE('Survey Progress'!$B$34, ""data!I2:L800""), 2, FALSE) = 0, ""Incomplete"", ""Complete"")))"),"") | E18: =IF(B18="Ineligible", 2, IF(AND(C18="Complete", D18="Complete"), 1, 0)) -> 0
B19: =IFERROR(__xludf.DUMMYFUNCTION("IF(ISERROR(VLOOKUP(A19, IMPORTRANGE('Survey Progress'!$B$32, ""data!H2:M800""), 5, FALSE)), """", IF(VLOOKUP(A19, IMPORTRANGE('Survey Progress'!$B$32, ""data!H2:M800""), 5, FALSE) = 1, ""Eligible"", ""Ineligible""))"),"Eligible") -> Eligible | C19: =IFERROR(__xludf.DUMMYFUNCTION("IF(A19="""", """", IF(ISERROR(VLOOKUP(A19, IMPORTRANGE('Survey Progress'!$B$33, ""data!I2:L800""), 1, FALSE)), ""No Survey"", IF(VLOOKUP(A19, IMPORTRANGE('Survey Progress'!$B$33, ""data!I2:L800""), 2, FALSE) = 0, ""Incomplete"", ""Complete"")))"),"") | D19: =IFERROR(__xludf.DUMMYFUNCTION("IF(A19="""", """", IF(ISERROR(VLOOKUP(A19, IMPORTRANGE('Survey Progress'!$B$34, ""data!I2:L800""), 1, FALSE)), ""No Survey"", IF(VLOOKUP(A19, IMPORTRANGE('Survey Progress'!$B$34, ""data!I2:L800""), 2, FALSE) = 0, ""Incomplete"", ""Complete"")))"),"") | E19: =IF(B19="Ineligible", 2, IF(AND(C19="Complete", D19="Complete"), 1, 0)) -> 0
B20: =IFERROR(__xludf.DUMMYFUNCTION("IF(ISERROR(VLOOKUP(A20, IMPORTRANGE('Survey Progress'!$B$32, ""data!H2:M800""), 5, FALSE)), """", IF(VLOOKUP(A20, IMPORTRANGE('Survey Progress'!$B$32, ""data!H2:M800""), 5, FALSE) = 1, ""Eligible"", ""Ineligible""))"),"Eligible") -> Eligible | C20: =IFERROR(__xludf.DUMMYFUNCTION("IF(A20="""", """", IF(ISERROR(VLOOKUP(A20, IMPORTRANGE('Survey Progress'!$B$33, ""data!I2:L800""), 1, FALSE)), ""No Survey"", IF(VLOOKUP(A20, IMPORTRANGE('Survey Progress'!$B$33, ""data!I2:L800""), 2, FALSE) = 0, ""Incomplete"", ""Complete"")))"),"") | D20: =IFERROR(__xludf.DUMMYFUNCTION("IF(A20="""", """", IF(ISERROR(VLOOKUP(A20, IMPORTRANGE('Survey Progress'!$B$34, ""data!I2:L800""), 1, FALSE)), ""No Survey"", IF(VLOOKUP(A20, IMPORTRANGE('Survey Progress'!$B$34, ""data!I2:L800""), 2, FALSE) = 0, ""Incomplete"", ""Complete"")))"),"") | E20: =IF(B20="Ineligible", 2, IF(AND(C20="Complete", D20="Complete"), 1, 0)) -> 0
B21: =IFERROR(__xludf.DUMMYFUNCTION("IF(ISERROR(VLOOKUP(A21, IMPORTRANGE('Survey Progress'!$B$32, ""data!H2:M800""), 5, FALSE)), """", IF(VLOOKUP(A21, IMPORTRANGE('Survey Progress'!$B$32, ""data!H2:M800""), 5, FALSE) = 1, ""Eligible"", ""Ineligible""))"),"Eligible") -> Eligible | C21: =IFERROR(__xludf.DUMMYFUNCTION("IF(A21="""", """", IF(ISERROR(VLOOKUP(A21, IMPORTRANGE('Survey Progress'!$B$33, ""data!I2:L800""), 1, FALSE)), ""No Survey"", IF(VLOOKUP(A21, IMPORTRANGE('Survey Progress'!$B$33, ""data!I2:L800""), 2, FALSE) = 0, ""Incomplete"", ""Complete"")))"),"") | D21: =IFERROR(__xludf.DUMMYFUNCTION("IF(A21="""", """", IF(ISERROR(VLOOKUP(A21, IMPORTRANGE('Survey Progress'!$B$34, ""data!I2:L800""), 1, FALSE)), ""No Survey"", IF(VLOOKUP(A21, IMPORTRANGE('Survey Progress'!$B$34, ""data!I2:L800""), 2, FALSE) = 0, ""Incomplete"", ""Complete"")))"),"") | E21: =IF(B21="Ineligible", 2, IF(AND(C21="Complete", D21="Complete"), 1, 0)) -> 0
B22: =IFERROR(__xludf.DUMMYFUNCTION("IF(ISERROR(VLOOKUP(A22, IMPORTRANGE('Survey Progress'!$B$32, ""data!H2:M800""), 5, FALSE)), """", IF(VLOOKUP(A22, IMPORTRANGE('Survey Progress'!$B$32, ""data!H2:M800""), 5, FALSE) = 1, ""Eligible"", ""Ineligible""))"),"Eligible") -> Eligible | C22: =IFERROR(__xludf.DUMMYFUNCTION("IF(A22="""", """", IF(ISERROR(VLOOKUP(A22, IMPORTRANGE('Survey Progress'!$B$33, ""data!I2:L800""), 1, FALSE)), ""No Survey"", IF(VLOOKUP(A22, IMPORTRANGE('Survey Progress'!$B$33, ""data!I2:L800""), 2, FALSE) = 0, ""Incomplete"", ""Complete"")))"),"") | D22: =IFERROR(__xludf.DUMMYFUNCTION("IF(A22="""", """", IF(ISERROR(VLOOKUP(A22, IMPORTRANGE('Survey Progress'!$B$34, ""data!I2:L800""), 1, FALSE)), ""No Survey"", IF(VLOOKUP(A22, IMPORTRANGE('Survey Progress'!$B$34, ""data!I2:L800""), 2, FALSE) = 0, ""Incomplete"", ""Complete"")))"),"") | E22: =IF(B22="Ineligible", 2, IF(AND(C22="Complete", D22="Complete"), 1, 0)) -> 0
B23: =IFERROR(__xludf.DUMMYFUNCTION("IF(ISERROR(VLOOKUP(A23, IMPORTRANGE('Survey Progress'!$B$32, ""data!H2:M800""), 5, FALSE)), """", IF(VLOOKUP(A23, IMPORTRANGE('Survey Progress'!$B$32, ""data!H2:M800""), 5, FALSE) = 1, ""Eligible"", ""Ineligible""))"),"Eligible") -> Eligible | C23: =IFERROR(__xludf.DUMMYFUNCTION("IF(A23="""", """", IF(ISERROR(VLOOKUP(A23, IMPORTRANGE('Survey Progress'!$B$33, ""data!I2:L800""), 1, FALSE)), ""No Survey"", IF(VLOOKUP(A23, IMPORTRANGE('Survey Progress'!$B$33, ""data!I2:L800""), 2, FALSE) = 0, ""Incomplete"", ""Complete"")))"),"") | D23: =IFERROR(__xludf.DUMMYFUNCTION("IF(A23="""", """", IF(ISERROR(VLOOKUP(A23, IMPORTRANGE('Survey Progress'!$B$34, ""data!I2:L800""), 1, FALSE)), ""No Survey"", IF(VLOOKUP(A23, IMPORTRANGE('Survey Progress'!$B$34, ""data!I2:L800""), 2, FALSE) = 0, ""Incomplete"", ""Complete"")))"),"") | E23: =IF(B23="Ineligible", 2, IF(AND(C23="Complete", D23="Complete"), 1, 0)) -> 0
B24: =IFERROR(__xludf.DUMMYFUNCTION("IF(ISERROR(VLOOKUP(A24, IMPORTRANGE('Survey Progress'!$B$32, ""data!H2:M800""), 5, FALSE)), """", IF(VLOOKUP(A24, IMPORTRANGE('Survey Progress'!$B$32, ""data!H2:M800""), 5, FALSE) = 1, ""Eligible"", ""Ineligible""))"),"Eligible") -> Eligible | C24: =IFERROR(__xludf.DUMMYFUNCTION("IF(A24="""", """", IF(ISERROR(VLOOKUP(A24, IMPORTRANGE('Survey Progress'!$B$33, ""data!I2:L800""), 1, FALSE)), ""No Survey"", IF(VLOOKUP(A24, IMPORTRANGE('Survey Progress'!$B$33, ""data!I2:L800""), 2, FALSE) = 0, ""Incomplete"", ""Complete"")))"),"") | D24: =IFERROR(__xludf.DUMMYFUNCTION("IF(A24="""", """", IF(ISERROR(VLOOKUP(A24, IMPORTRANGE('Survey Progress'!$B$34, ""data!I2:L800""), 1, FALSE)), ""No Survey"", IF(VLOOKUP(A24, IMPORTRANGE('Survey Progress'!$B$34, ""data!I2:L800""), 2, FALSE) = 0, ""Incomplete"", ""Complete"")))"),"") | E24: =IF(B24="Ineligible", 2, IF(AND(C24="Complete", D24="Complete"), 1, 0)) -> 0
B25: =IFERROR(__xludf.DUMMYFUNCTION("IF(ISERROR(VLOOKUP(A25, IMPORTRANGE('Survey Progress'!$B$32, ""data!H2:M800""), 5, FALSE)), """", IF(VLOOKUP(A25, IMPORTRANGE('Survey Progress'!$B$32, ""data!H2:M800""), 5, FALSE) = 1, ""Eligible"", ""Ineligible""))"),"Eligible") -> Eligible | C25: =IFERROR(__xludf.DUMMYFUNCTION("IF(A25="""", """", IF(ISERROR(VLOOKUP(A25, IMPORTRANGE('Survey Progress'!$B$33, ""data!I2:L800""), 1, FALSE)), ""No Survey"", IF(VLOOKUP(A25, IMPORTRANGE('Survey Progress'!$B$33, ""data!I2:L800""), 2, FALSE) = 0, ""Incomplete"", ""Complete"")))"),"") | D25: =IFERROR(__xludf.DUMMYFUNCTION("IF(A25="""", """", IF(ISERROR(VLOOKUP(A25, IMPORTRANGE('Survey Progress'!$B$34, ""data!I2:L800""), 1, FALSE)), ""No Survey"", IF(VLOOKUP(A25, IMPORTRANGE('Survey Progress'!$B$34, ""data!I2:L800""), 2, FALSE) = 0, ""Incomplete"", ""Complete"")))"),"") | E25: =IF(B25="Ineligible", 2, IF(AND(C25="Complete", D25="Complete"), 1, 0)) -> 0
B26: =IFERROR(__xludf.DUMMYFUNCTION("IF(ISERROR(VLOOKUP(A26, IMPORTRANGE('Survey Progress'!$B$32, ""data!H2:M800""), 5, FALSE)), """", IF(VLOOKUP(A26, IMPORTRANGE('Survey Progress'!$B$32, ""data!H2:M800""), 5, FALSE) = 1, ""Eligible"", ""Ineligible""))"),"Eligible") -> Eligible | C26: =IFERROR(__xludf.DUMMYFUNCTION("IF(A26="""", """", IF(ISERROR(VLOOKUP(A26, IMPORTRANGE('Survey Progress'!$B$33, ""data!I2:L800""), 1, FALSE)), ""No Survey"", IF(VLOOKUP(A26, IMPORTRANGE('Survey Progress'!$B$33, ""data!I2:L800""), 2, FALSE) = 0, ""Incomplete"", ""Complete"")))"),"") | D26: =IFERROR(__xludf.DUMMYFUNCTION("IF(A26="""", """", IF(ISERROR(VLOOKUP(A26, IMPORTRANGE('Survey Progress'!$B$34, ""data!I2:L800""), 1, FALSE)), ""No Survey"", IF(VLOOKUP(A26, IMPORTRANGE('Survey Progress'!$B$34, ""data!I2:L800""), 2, FALSE) = 0, ""Incomplete"", ""Complete"")))"),"") | E26: =IF(B26="Ineligible", 2, IF(AND(C26="Complete", D26="Complete"), 1, 0)) -> 0
B27: =IFERROR(__xludf.DUMMYFUNCTION("IF(ISERROR(VLOOKUP(A27, IMPORTRANGE('Survey Progress'!$B$32, ""data!H2:M800""), 5, FALSE)), """", IF(VLOOKUP(A27, IMPORTRANGE('Survey Progress'!$B$32, ""data!H2:M800""), 5, FALSE) = 1, ""Eligible"", ""Ineligible""))"),"Eligible") -> Eligible | C27: =IFERROR(__xludf.DUMMYFUNCTION("IF(A27="""", """", IF(ISERROR(VLOOKUP(A27, IMPORTRANGE('Survey Progress'!$B$33, ""data!I2:L800""), 1, FALSE)), ""No Survey"", IF(VLOOKUP(A27, IMPORTRANGE('Survey Progress'!$B$33, ""data!I2:L800""), 2, FALSE) = 0, ""Incomplete"", ""Complete"")))"),"") | D27: =IFERROR(__xludf.DUMMYFUNCTION("IF(A27="""", """", IF(ISERROR(VLOOKUP(A27, IMPORTRANGE('Survey Progress'!$B$34, ""data!I2:L800""), 1, FALSE)), ""No Survey"", IF(VLOOKUP(A27, IMPORTRANGE('Survey Progress'!$B$34, ""data!I2:L800""), 2, FALSE) = 0, ""Incomplete"", ""Complete"")))"),"") | E27: =IF(B27="Ineligible", 2, IF(AND(C27="Complete", D27="Complete"), 1, 0)) -> 0
B28: =IFERROR(__xludf.DUMMYFUNCTION("IF(ISERROR(VLOOKUP(A28, IMPORTRANGE('Survey Progress'!$B$32, ""data!H2:M800""), 5, FALSE)), """", IF(VLOOKUP(A28, IMPORTRANGE('Survey Progress'!$B$32, ""data!H2:M800""), 5, FALSE) = 1, ""Eligible"", ""Ineligible""))"),"Eligible") -> Eligible | C28: =IFERROR(__xludf.DUMMYFUNCTION("IF(A28="""", """", IF(ISERROR(VLOOKUP(A28, IMPORTRANGE('Survey Progress'!$B$33, ""data!I2:L800""), 1, FALSE)), ""No Survey"", IF(VLOOKUP(A28, IMPORTRANGE('Survey Progress'!$B$33, ""data!I2:L800""), 2, FALSE) = 0, ""Incomplete"", ""Complete"")))"),"") | D28: =IFERROR(__xludf.DUMMYFUNCTION("IF(A28="""", """", IF(ISERROR(VLOOKUP(A28, IMPORTRANGE('Survey Progress'!$B$34, ""data!I2:L800""), 1, FALSE)), ""No Survey"", IF(VLOOKUP(A28, IMPORTRANGE('Survey Progress'!$B$34, ""data!I2:L800""), 2, FALSE) = 0, ""Incomplete"", ""Complete"")))"),"") | E28: =IF(B28="Ineligible", 2, IF(AND(C28="Complete", D28="Complete"), 1, 0)) -> 0
B29: =IFERROR(__xludf.DUMMYFUNCTION("IF(ISERROR(VLOOKUP(A29, IMPORTRANGE('Survey Progress'!$B$32, ""data!H2:M800""), 5, FALSE)), """", IF(VLOOKUP(A29, IMPORTRANGE('Survey Progress'!$B$32, ""data!H2:M800""), 5, FALSE) = 1, ""Eligible"", ""Ineligible""))"),"Eligible") -> Eligible | C29: =IFERROR(__xludf.DUMMYFUNCTION("IF(A29="""", """", IF(ISERROR(VLOOKUP(A29, IMPORTRANGE('Survey Progress'!$B$33, ""data!I2:L800""), 1, FALSE)), ""No Survey"", IF(VLOOKUP(A29, IMPORTRANGE('Survey Progress'!$B$33, ""data!I2:L800""), 2, FALSE) = 0, ""Incomplete"", ""Complete"")))"),"") | D29: =IFERROR(__xludf.DUMMYFUNCTION("IF(A29="""", """", IF(ISERROR(VLOOKUP(A29, IMPORTRANGE('Survey Progress'!$B$34, ""data!I2:L800""), 1, FALSE)), ""No Survey"", IF(VLOOKUP(A29, IMPORTRANGE('Survey Progress'!$B$34, ""data!I2:L800""), 2, FALSE) = 0, ""Incomplete"", ""Complete"")))"),"") | E29: =IF(B29="Ineligible", 2, IF(AND(C29="Complete", D29="Complete"), 1, 0)) -> 0
B30: =IFERROR(__xludf.DUMMYFUNCTION("IF(ISERROR(VLOOKUP(A30, IMPORTRANGE('Survey Progress'!$B$32, ""data!H2:M800""), 5, FALSE)), """", IF(VLOOKUP(A30, IMPORTRANGE('Survey Progress'!$B$32, ""data!H2:M800""), 5, FALSE) = 1, ""Eligible"", ""Ineligible""))"),"Eligible") -> Eligible | C30: =IFERROR(__xludf.DUMMYFUNCTION("IF(A30="""", """", IF(ISERROR(VLOOKUP(A30, IMPORTRANGE('Survey Progress'!$B$33, ""data!I2:L800""), 1, FALSE)), ""No Survey"", IF(VLOOKUP(A30, IMPORTRANGE('Survey Progress'!$B$33, ""data!I2:L800""), 2, FALSE) = 0, ""Incomplete"", ""Complete"")))"),"") | D30: =IFERROR(__xludf.DUMMYFUNCTION("IF(A30="""", """", IF(ISERROR(VLOOKUP(A30, IMPORTRANGE('Survey Progress'!$B$34, ""data!I2:L800""), 1, FALSE)), ""No Survey"", IF(VLOOKUP(A30, IMPORTRANGE('Survey Progress'!$B$34, ""data!I2:L800""), 2, FALSE) = 0, ""Incomplete"", ""Complete"")))"),"") | E30: =IF(B30="Ineligible", 2, IF(AND(C30="Complete", D30="Complete"), 1, 0)) -> 0
B31: =IFERROR(__xludf.DUMMYFUNCTION("IF(ISERROR(VLOOKUP(A31, IMPORTRANGE('Survey Progress'!$B$32, ""data!H2:M800""), 5, FALSE)), """", IF(VLOOKUP(A31, IMPORTRANGE('Survey Progress'!$B$32, ""data!H2:M800""), 5, FALSE) = 1, ""Eligible"", ""Ineligible""))"),"Eligible") -> Eligible | C31: =IFERROR(__xludf.DUMMYFUNCTION("IF(A31="""", """", IF(ISERROR(VLOOKUP(A31, IMPORTRANGE('Survey Progress'!$B$33, ""data!I2:L800""), 1, FALSE)), ""No Survey"", IF(VLOOKUP(A31, IMPORTRANGE('Survey Progress'!$B$33, ""data!I2:L800""), 2, FALSE) = 0, ""Incomplete"", ""Complete"")))"),"") | D31: =IFERROR(__xludf.DUMMYFUNCTION("IF(A31="""", """", IF(ISERROR(VLOOKUP(A31, IMPORTRANGE('Survey Progress'!$B$34, ""data!I2:L800""), 1, FALSE)), ""No Survey"", IF(VLOOKUP(A31, IMPORTRANGE('Survey Progress'!$B$34, ""data!I2:L800""), 2, FALSE) = 0, ""Incomplete"", ""Complete"")))"),"") | E31: =IF(B31="Ineligible", 2, IF(AND(C31="Complete", D31="Complete"), 1, 0)) -> 0
B32: =IFERROR(__xludf.DUMMYFUNCTION("IF(ISERROR(VLOOKUP(A32, IMPORTRANGE('Survey Progress'!$B$32, ""data!H2:M800""), 5, FALSE)), """", IF(VLOOKUP(A32, IMPORTRANGE('Survey Progress'!$B$32, ""data!H2:M800""), 5, FALSE) = 1, ""Eligible"", ""Ineligible""))"),"Eligible") -> Eligible | C32: =IFERROR(__xludf.DUMMYFUNCTION("IF(A32="""", """", IF(ISERROR(VLOOKUP(A32, IMPORTRANGE('Survey Progress'!$B$33, ""data!I2:L800""), 1, FALSE)), ""No Survey"", IF(VLOOKUP(A32, IMPORTRANGE('Survey Progress'!$B$33, ""data!I2:L800""), 2, FALSE) = 0, ""Incomplete"", ""Complete"")))"),"") | D32: =IFERROR(__xludf.DUMMYFUNCTION("IF(A32="""", """", IF(ISERROR(VLOOKUP(A32, IMPORTRANGE('Survey Progress'!$B$34, ""data!I2:L800""), 1, FALSE)), ""No Survey"", IF(VLOOKUP(A32, IMPORTRANGE('Survey Progress'!$B$34, ""data!I2:L800""), 2, FALSE) = 0, ""Incomplete"", ""Complete"")))"),"") | E32: =IF(B32="Ineligible", 2, IF(AND(C32="Complete", D32="Complete"), 1, 0)) -> 0
B33: =IFERROR(__xludf.DUMMYFUNCTION("IF(ISERROR(VLOOKUP(A33, IMPORTRANGE('Survey Progress'!$B$32, ""data!H2:M800""), 5, FALSE)), """", IF(VLOOKUP(A33, IMPORTRANGE('Survey Progress'!$B$32, ""data!H2:M800""), 5, FALSE) = 1, ""Eligible"", ""Ineligible""))"),"Eligible") -> Eligible | C33: =IFERROR(__xludf.DUMMYFUNCTION("IF(A33="""", """", IF(ISERROR(VLOOKUP(A33, IMPORTRANGE('Survey Progress'!$B$33, ""data!I2:L800""), 1, FALSE)), ""No Survey"", IF(VLOOKUP(A33, IMPORTRANGE('Survey Progress'!$B$33, ""data!I2:L800""), 2, FALSE) = 0, ""Incomplete"", ""Complete"")))"),"") | D33: =IFERROR(__xludf.DUMMYFUNCTION("IF(A33="""", """", IF(ISERROR(VLOOKUP(A33, IMPORTRANGE('Survey Progress'!$B$34, ""data!I2:L800""), 1, FALSE)), ""No Survey"", IF(VLOOKUP(A33, IMPORTRANGE('Survey Progress'!$B$34, ""data!I2:L800""), 2, FALSE) = 0, ""Incomplete"", ""Complete"")))"),"") | E33: =IF(B33="Ineligible", 2, IF(AND(C33="Complete", D33="Complete"), 1, 0)) -> 0
B34: =IFERROR(__xludf.DUMMYFUNCTION("IF(ISERROR(VLOOKUP(A34, IMPORTRANGE('Survey Progress'!$B$32, ""data!H2:M800""), 5, FALSE)), """", IF(VLOOKUP(A34, IMPORTRANGE('Survey Progress'!$B$32, ""data!H2:M800""), 5, FALSE) = 1, ""Eligible"", ""Ineligible""))"),"Eligible") -> Eligible | C34: =IFERROR(__xludf.DUMMYFUNCTION("IF(A34="""", """", IF(ISERROR(VLOOKUP(A34, IMPORTRANGE('Survey Progress'!$B$33, ""data!I2:L800""), 1, FALSE)), ""No Survey"", IF(VLOOKUP(A34, IMPORTRANGE('Survey Progress'!$B$33, ""data!I2:L800""), 2, FALSE) = 0, ""Incomplete"", ""Complete"")))"),"") | D34: =IFERROR(__xludf.DUMMYFUNCTION("IF(A34="""", """", IF(ISERROR(VLOOKUP(A34, IMPORTRANGE('Survey Progress'!$B$34, ""data!I2:L800""), 1, FALSE)), ""No Survey"", IF(VLOOKUP(A34, IMPORTRANGE('Survey Progress'!$B$34, ""data!I2:L800""), 2, FALSE) = 0, ""Incomplete"", ""Complete"")))"),"") | E34: =IF(B34="Ineligible", 2, IF(AND(C34="Complete", D34="Complete"), 1, 0)) -> 0
B35: =IFERROR(__xludf.DUMMYFUNCTION("IF(ISERROR(VLOOKUP(A35, IMPORTRANGE('Survey Progress'!$B$32, ""data!H2:M800""), 5, FALSE)), """", IF(VLOOKUP(A35, IMPORTRANGE('Survey Progress'!$B$32, ""data!H2:M800""), 5, FALSE) = 1, ""Eligible"", ""Ineligible""))"),"Eligible") -> Eligible | C35: =IFERROR(__xludf.DUMMYFUNCTION("IF(A35="""", """", IF(ISERROR(VLOOKUP(A35, IMPORTRANGE('Survey Progress'!$B$33, ""data!I2:L800""), 1, FALSE)), ""No Survey"", IF(VLOOKUP(A35, IMPORTRANGE('Survey Progress'!$B$33, ""data!I2:L800""), 2, FALSE) = 0, ""Incomplete"", ""Complete"")))"),"") | D35: =IFERROR(__xludf.DUMMYFUNCTION("IF(A35="""", """", IF(ISERROR(VLOOKUP(A35, IMPORTRANGE('Survey Progress'!$B$34, ""data!I2:L800""), 1, FALSE)), ""No Survey"", IF(VLOOKUP(A35, IMPORTRANGE('Survey Progress'!$B$34, ""data!I2:L800""), 2, FALSE) = 0, ""Incomplete"", ""Complete"")))"),"") | E35: =IF(B35="Ineligible", 2, IF(AND(C35="Complete", D35="Complete"), 1, 0)) -> 0
B36: =IFERROR(__xludf.DUMMYFUNCTION("IF(ISERROR(VLOOKUP(A36, IMPORTRANGE('Survey Progress'!$B$32, ""data!H2:M800""), 5, FALSE)), """", IF(VLOOKUP(A36, IMPORTRANGE('Survey Progress'!$B$32, ""data!H2:M800""), 5, FALSE) = 1, ""Eligible"", ""Ineligible""))"),"Eligible") -> Eligible | C36: =IFERROR(__xludf.DUMMYFUNCTION("IF(A36="""", """", IF(ISERROR(VLOOKUP(A36, IMPORTRANGE('Survey Progress'!$B$33, ""data!I2:L800""), 1, FALSE)), ""No Survey"", IF(VLOOKUP(A36, IMPORTRANGE('Survey Progress'!$B$33, ""data!I2:L800""), 2, FALSE) = 0, ""Incomplete"", ""Complete"")))"),"") | D36: =IFERROR(__xludf.DUMMYFUNCTION("IF(A36="""", """", IF(ISERROR(VLOOKUP(A36, IMPORTRANGE('Survey Progress'!$B$34, ""data!I2:L800""), 1, FALSE)), ""No Survey"", IF(VLOOKUP(A36, IMPORTRANGE('Survey Progress'!$B$34, ""data!I2:L800""), 2, FALSE) = 0, ""Incomplete"", ""Complete"")))"),"") | E36: =IF(B36="Ineligible", 2, IF(AND(C36="Complete", D36="Complete"), 1, 0)) -> 0
B37: =IFERROR(__xludf.DUMMYFUNCTION("IF(ISERROR(VLOOKUP(A37, IMPORTRANGE('Survey Progress'!$B$32, ""data!H2:M800""), 5, FALSE)), """", IF(VLOOKUP(A37, IMPORTRANGE('Survey Progress'!$B$32, ""data!H2:M800""), 5, FALSE) = 1, ""Eligible"", ""Ineligible""))"),"Eligible") -> Eligible | C37: =IFERROR(__xludf.DUMMYFUNCTION("IF(A37="""", """", IF(ISERROR(VLOOKUP(A37, IMPORTRANGE('Survey Progress'!$B$33, ""data!I2:L800""), 1, FALSE)), ""No Survey"", IF(VLOOKUP(A37, IMPORTRANGE('Survey Progress'!$B$33, ""data!I2:L800""), 2, FALSE) = 0, ""Incomplete"", ""Complete"")))"),"") | D37: =IFERROR(__xludf.DUMMYFUNCTION("IF(A37="""", """", IF(ISERROR(VLOOKUP(A37, IMPORTRANGE('Survey Progress'!$B$34, ""data!I2:L800""), 1, FALSE)), ""No Survey"", IF(VLOOKUP(A37, IMPORTRANGE('Survey Progress'!$B$34, ""data!I2:L800""), 2, FALSE) = 0, ""Incomplete"", ""Complete"")))"),"") | E37: =IF(B37="Ineligible", 2, IF(AND(C37="Complete", D37="Complete"), 1, 0)) -> 0
B38: =IFERROR(__xludf.DUMMYFUNCTION("IF(ISERROR(VLOOKUP(A38, IMPORTRANGE('Survey Progress'!$B$32, ""data!H2:M800""), 5, FALSE)), """", IF(VLOOKUP(A38, IMPORTRANGE('Survey Progress'!$B$32, ""data!H2:M800""), 5, FALSE) = 1, ""Eligible"", ""Ineligible""))"),"Eligible") -> Eligible | C38: =IFERROR(__xludf.DUMMYFUNCTION("IF(A38="""", """", IF(ISERROR(VLOOKUP(A38, IMPORTRANGE('Survey Progress'!$B$33, ""data!I2:L800""), 1, FALSE)), ""No Survey"", IF(VLOOKUP(A38, IMPORTRANGE('Survey Progress'!$B$33, ""data!I2:L800""), 2, FALSE) = 0, ""Incomplete"", ""Complete"")))"),"") | D38: =IFERROR(__xludf.DUMMYFUNCTION("IF(A38="""", """", IF(ISERROR(VLOOKUP(A38, IMPORTRANGE('Survey Progress'!$B$34, ""data!I2:L800""), 1, FALSE)), ""No Survey"", IF(VLOOKUP(A38, IMPORTRANGE('Survey Progress'!$B$34, ""data!I2:L800""), 2, FALSE) = 0, ""Incomplete"", ""Complete"")))"),"") | E38: =IF(B38="Ineligible", 2, IF(AND(C38="Complete", D38="Complete"), 1, 0)) -> 0
B39: =IFERROR(__xludf.DUMMYFUNCTION("IF(ISERROR(VLOOKUP(A39, IMPORTRANGE('Survey Progress'!$B$32, ""data!H2:M800""), 5, FALSE)), """", IF(VLOOKUP(A39, IMPORTRANGE('Survey Progress'!$B$32, ""data!H2:M800""), 5, FALSE) = 1, ""Eligible"", ""Ineligible""))"),"Eligible") -> Eligible | C39: =IFERROR(__xludf.DUMMYFUNCTION("IF(A39="""", """", IF(ISERROR(VLOOKUP(A39, IMPORTRANGE('Survey Progress'!$B$33, ""data!I2:L800""), 1, FALSE)), ""No Survey"", IF(VLOOKUP(A39, IMPORTRANGE('Survey Progress'!$B$33, ""data!I2:L800""), 2, FALSE) = 0, ""Incomplete"", ""Complete"")))"),"") | D39: =IFERROR(__xludf.DUMMYFUNCTION("IF(A39="""", """", IF(ISERROR(VLOOKUP(A39, IMPORTRANGE('Survey Progress'!$B$34, ""data!I2:L800""), 1, FALSE)), ""No Survey"", IF(VLOOKUP(A39, IMPORTRANGE('Survey Progress'!$B$34, ""data!I2:L800""), 2, FALSE) = 0, ""Incomplete"", ""Complete"")))"),"") | E39: =IF(B39="Ineligible", 2, IF(AND(C39="Complete", D39="Complete"), 1, 0)) -> 0
B40: =IFERROR(__xludf.DUMMYFUNCTION("IF(ISERROR(VLOOKUP(A40, IMPORTRANGE('Survey Progress'!$B$32, ""data!H2:M800""), 5, FALSE)), """", IF(VLOOKUP(A40, IMPORTRANGE('Survey Progress'!$B$32, ""data!H2:M800""), 5, FALSE) = 1, ""Eligible"", ""Ineligible""))"),"Eligible") -> Eligible | C40: =IFERROR(__xludf.DUMMYFUNCTION("IF(A40="""", """", IF(ISERROR(VLOOKUP(A40, IMPORTRANGE('Survey Progress'!$B$33, ""data!I2:L800""), 1, FALSE)), ""No Survey"", IF(VLOOKUP(A40, IMPORTRANGE('Survey Progress'!$B$33, ""data!I2:L800""), 2, FALSE) = 0, ""Incomplete"", ""Complete"")))"),"") | D40: =IFERROR(__xludf.DUMMYFUNCTION("IF(A40="""", """", IF(ISERROR(VLOOKUP(A40, IMPORTRANGE('Survey Progress'!$B$34, ""data!I2:L800""), 1, FALSE)), ""No Survey"", IF(VLOOKUP(A40, IMPORTRANGE('Survey Progress'!$B$34, ""data!I2:L800""), 2, FALSE) = 0, ""Incomplete"", ""Complete"")))"),"") | E40: =IF(B40="Ineligible", 2, IF(AND(C40="Complete", D40="Complete"), 1, 0)) -> 0
B41: =IFERROR(__xludf.DUMMYFUNCTION("IF(ISERROR(VLOOKUP(A41, IMPORTRANGE('Survey Progress'!$B$32, ""data!H2:M800""), 5, FALSE)), """", IF(VLOOKUP(A41, IMPORTRANGE('Survey Progress'!$B$32, ""data!H2:M800""), 5, FALSE) = 1, ""Eligible"", ""Ineligible""))"),"Eligible") -> Eligible | C41: =IFERROR(__xludf.DUMMYFUNCTION("IF(A41="""", """", IF(ISERROR(VLOOKUP(A41, IMPORTRANGE('Survey Progress'!$B$33, ""data!I2:L800""), 1, FALSE)), ""No Survey"", IF(VLOOKUP(A41, IMPORTRANGE('Survey Progress'!$B$33, ""data!I2:L800""), 2, FALSE) = 0, ""Incomplete"", ""Complete"")))"),"") | D41: =IFERROR(__xludf.DUMMYFUNCTION("IF(A41="""", """", IF(ISERROR(VLOOKUP(A41, IMPORTRANGE('Survey Progress'!$B$34, ""data!I2:L800""), 1, FALSE)), ""No Survey"", IF(VLOOKUP(A41, IMPORTRANGE('Survey Progress'!$B$34, ""data!I2:L800""), 2, FALSE) = 0, ""Incomplete"", ""Complete"")))"),"") | E41: =IF(B41="Ineligible", 2, IF(AND(C41="Complete", D41="Complete"), 1, 0)) -> 0
...

Sheet Enumerators
A1: Submitted Surveys
C2: 2022-01-11 | D2: 2022-01-12 | E2: 2022-01-13 | F2: 2022-01-14 | G2: 2022-01-15 | H2: 2022-01-16 | I2: 2022-01-17 | J2: 2022-01-18 | K2: 2022-01-19 | L2: 2022-01-20 | M2: 2022-01-21 | N2: 2022-01-22 | O2: 2022-01-23 | P2: 2022-01-24 | Q2: 2022-01-25 | R2: 2022-01-26 | S2: 2022-01-27 | T2: 2022-01-28
A3: Imarane Issa Rabo | B3: Screening & HHH | C3: =IFERROR(__xludf.DUMMYFUNCTION("COUNTIFS(IMPORTRANGE('Survey Progress'!$B$32, ""data!$B$2:$B$800""), ""=""&$A3, IMPORTRANGE('Survey Progress'!$B$32, ""data!$S$2:$S$800""), ""*""&C$2&""*"")"),0.0) -> 0 | D3: =IFERROR(__xludf.DUMMYFUNCTION("COUNTIFS(IMPORTRANGE('Survey Progress'!$B$32, ""data!$B$2:$B$800""), ""=""&$A3, IMPORTRANGE('Survey Progress'!$B$32, ""data!$S$2:$S$800""), ""*""&D$2&""*"")"),0.0) -> 0 | E3: =IFERROR(__xludf.DUMMYFUNCTION("COUNTIFS(IMPORTRANGE('Survey Progress'!$B$32, ""data!$B$2:$B$800""), ""=""&$A3, IMPORTRANGE('Survey Progress'!$B$32, ""data!$S$2:$S$800""), ""*""&E$2&""*"")"),0.0) -> 0 | F3: =IFERROR(__xludf.DUMMYFUNCTION("COUNTIFS(IMPORTRANGE('Survey Progress'!$B$32, ""data!$B$2:$B$800""), ""=""&$A3, IMPORTRANGE('Survey Progress'!$B$32, ""data!$S$2:$S$800""), ""*""&F$2&""*"")"),0.0) -> 0 | G3: =IFERROR(__xludf.DUMMYFUNCTION("COUNTIFS(IMPORTRANGE('Survey Progress'!$B$32, ""data!$B$2:$B$800""), ""=""&$A3, IMPORTRANGE('Survey Progress'!$B$32, ""data!$S$2:$S$800""), ""*""&G$2&""*"")"),0.0) -> 0 | H3: =IFERROR(__xludf.DUMMYFUNCTION("COUNTIFS(IMPORTRANGE('Survey Progress'!$B$32, ""data!$B$2:$B$800""), ""=""&$A3, IMPORTRANGE('Survey Progress'!$B$32, ""data!$S$2:$S$800""), ""*""&H$2&""*"")"),0.0) -> 0 | I3: =IFERROR(__xludf.DUMMYFUNCTION("COUNTIFS(IMPORTRANGE('Survey Progress'!$B$32, ""data!$B$2:$B$800""), ""=""&$A3, IMPORTRANGE('Survey Progress'!$B$32, ""data!$S$2:$S$800""), ""*""&I$2&""*"")"),0.0) -> 0 | J3: =IFERROR(__xludf.DUMMYFUNCTION("COUNTIFS(IMPORTRANGE('Survey Progress'!$B$32, ""data!$B$2:$B$800""), ""=""&$A3, IMPORTRANGE('Survey Progress'!$B$32, ""data!$S$2:$S$800""), ""*""&J$2&""*"")"),0.0) -> 0 | K3: =IFERROR(__xludf.DUMMYFUNCTION("COUNTIFS(IMPORTRANGE('Survey Progress'!$B$32, ""data!$B$2:$B$800""), ""=""&$A3, IMPORTRANGE('Survey Progress'!$B$32, ""data!$S$2:$S$800""), ""*""&K$2&""*"")"),0.0) -> 0 | L3: =IFERROR(__xludf.DUMMYFUNCTION("COUNTIFS(IMPORTRANGE('Survey Progress'!$B$32, ""data!$B$2:$B$800""), ""=""&$A3, IMPORTRANGE('Survey Progress'!$B$32, ""data!$S$2:$S$800""), ""*""&L$2&""*"")"),0.0) -> 0 | M3: =IFERROR(__xludf.DUMMYFUNCTION("COUNTIFS(IMPORTRANGE('Survey Progress'!$B$32, ""data!$B$2:$B$800""), ""=""&$A3, IMPORTRANGE('Survey Progress'!$B$32, ""data!$S$2:$S$800""), ""*""&M$2&""*"")"),0.0) -> 0 | N3: =IFERROR(__xludf.DUMMYFUNCTION("COUNTIFS(IMPORTRANGE('Survey Progress'!$B$32, ""data!$B$2:$B$800""), ""=""&$A3, IMPORTRANGE('Survey Progress'!$B$32, ""data!$S$2:$S$800""), ""*""&N$2&""*"")"),0.0) -> 0 | O3: =IFERROR(__xludf.DUMMYFUNCTION("COUNTIFS(IMPORTRANGE('Survey Progress'!$B$32, ""data!$B$2:$B$800""), ""=""&$A3, IMPORTRANGE('Survey Progress'!$B$32, ""data!$S$2:$S$800""), ""*""&O$2&""*"")"),0.0) -> 0 | P3: =IFERROR(__xludf.DUMMYFUNCTION("COUNTIFS(IMPORTRANGE('Survey Progress'!$B$32, ""data!$B$2:$B$800""), ""=""&$A3, IMPORTRANGE('Survey Progress'!$B$32, ""data!$S$2:$S$800""), ""*""&P$2&""*"")"),0.0) -> 0 | Q3: =IFERROR(__xludf.DUMMYFUNCTION("COUNTIFS(IMPORTRANGE('Survey Progress'!$B$32, ""data!$B$2:$B$800""), ""=""&$A3, IMPORTRANGE('Survey Progress'!$B$32, ""data!$S$2:$S$800""), ""*""&Q$2&""*"")"),0.0) -> 0 | R3: =IFERROR(__xludf.DUMMYFUNCTION("COUNTIFS(IMPORTRANGE('Survey Progress'!$B$32, ""data!$B$2:$B$800""), ""=""&$A3, IMPORTRANGE('Survey Progress'!$B$32, ""data!$S$2:$S$800""), ""*""&R$2&""*"")"),0.0) -> 0 | S3: =IFERROR(__xludf.DUMMYFUNCTION("COUNTIFS(IMPORTRANGE('Survey Progress'!$B$32, ""data!$B$2:$B$800""), ""=""&$A3, IMPORTRANGE('Survey Progress'!$B$32, ""data!$S$2:$S$800""), ""*""&S$2&""*"")"),0.0) -> 0 | T3: =IFERROR(__xludf.DUMMYFUNCTION("COUNTIFS(IMPORTRANGE('Survey Progress'!$B$32, ""data!$B$2:$B$800""), ""=""&$A3, IMPORTRANGE('Survey Progress'!$B$32, ""data!$S$2:$S$800""), ""*""&T$2&""*"")"),0.0) -> 0
A4: Imarane Issa Rabo | B4: PM | C4: =IFERROR(__xludf.DUMMYFUNCTION("COUNTIFS(IMPORTRANGE('Survey Progress'!$B$33, ""data!B2:B800""), ""=""&$A4, IMPORTRANGE('Survey Progress'!$B$33, ""data!O2:O800""), ""*""&C$2&""*"")"),0.0) -> 0 | D4: =IFERROR(__xludf.DUMMYFUNCTION("COUNTIFS(IMPORTRANGE('Survey Progress'!$B$33, ""data!B2:B800""), ""=""&$A4, IMPORTRANGE('Survey Progress'!$B$33, ""data!O2:O800""), ""*""&D$2&""*"")"),0.0) -> 0 | E4: =IFERROR(__xludf.DUMMYFUNCTION("COUNTIFS(IMPORTRANGE('Survey Progress'!$B$33, ""data!B2:B800""), ""=""&$A4, IMPORTRANGE('Survey Progress'!$B$33, ""data!O2:O800""), ""*""&E$2&""*"")"),0.0) -> 0 | F4: =IFERROR(__xludf.DUMMYFUNCTION("COUNTIFS(IMPORTRANGE('Survey Progress'!$B$33, ""data!B2:B800""), ""=""&$A4, IMPORTRANGE('Survey Progress'!$B$33, ""data!O2:O800""), ""*""&F$2&""*"")"),0.0) -> 0 | G4: =IFERROR(__xludf.DUMMYFUNCTION("COUNTIFS(IMPORTRANGE('Survey Progress'!$B$33, ""data!B2:B800""), ""=""&$A4, IMPORTRANGE('Survey Progress'!$B$33, ""data!O2:O800""), ""*""&G$2&""*"")"),0.0) -> 0 | H4: =IFERROR(__xludf.DUMMYFUNCTION("COUNTIFS(IMPORTRANGE('Survey Progress'!$B$33, ""data!B2:B800""), ""=""&$A4, IMPORTRANGE('Survey Progress'!$B$33, ""data!O2:O800""), ""*""&H$2&""*"")"),0.0) -> 0 | I4: =IFERROR(__xludf.DUMMYFUNCTION("COUNTIFS(IMPORTRANGE('Survey Progress'!$B$33, ""data!B2:B800""), ""=""&$A4, IMPORTRANGE('Survey Progress'!$B$33, ""data!O2:O800""), ""*""&I$2&""*"")"),0.0) -> 0 | J4: =IFERROR(__xludf.DUMMYFUNCTION("COUNTIFS(IMPORTRANGE('Survey Progress'!$B$33, ""data!B2:B800""), ""=""&$A4, IMPORTRANGE('Survey Progress'!$B$33, ""data!O2:O800""), ""*""&J$2&""*"")"),0.0) -> 0 | K4: =IFERROR(__xludf.DUMMYFUNCTION("COUNTIFS(IMPORTRANGE('Survey Progress'!$B$33, ""data!B2:B800""), ""=""&$A4, IMPORTRANGE('Survey Progress'!$B$33, ""data!O2:O800""), ""*""&K$2&""*"")"),0.0) -> 0 | L4: =IFERROR(__xludf.DUMMYFUNCTION("COUNTIFS(IMPORTRANGE('Survey Progress'!$B$33, ""data!B2:B800""), ""=""&$A4, IMPORTRANGE('Survey Progress'!$B$33, ""data!O2:O800""), ""*""&L$2&""*"")"),0.0) -> 0 | M4: =IFERROR(__xludf.DUMMYFUNCTION("COUNTIFS(IMPORTRANGE('Survey Progress'!$B$33, ""data!B2:B800""), ""=""&$A4, IMPORTRANGE('Survey Progress'!$B$33, ""data!O2:O800""), ""*""&M$2&""*"")"),0.0) -> 0 | N4: =IFERROR(__xludf.DUMMYFUNCTION("COUNTIFS(IMPORTRANGE('Survey Progress'!$B$33, ""data!B2:B800""), ""=""&$A4, IMPORTRANGE('Survey Progress'!$B$33, ""data!O2:O800""), ""*""&N$2&""*"")"),0.0) -> 0 | O4: =IFERROR(__xludf.DUMMYFUNCTION("COUNTIFS(IMPORTRANGE('Survey Progress'!$B$33, ""data!B2:B800""), ""=""&$A4, IMPORTRANGE('Survey Progress'!$B$33, ""data!O2:O800""), ""*""&O$2&""*"")"),0.0) -> 0 | P4: =IFERROR(__xludf.DUMMYFUNCTION("COUNTIFS(IMPORTRANGE('Survey Progress'!$B$33, ""data!B2:B800""), ""=""&$A4, IMPORTRANGE('Survey Progress'!$B$33, ""data!O2:O800""), ""*""&P$2&""*"")"),0.0) -> 0 | Q4: =IFERROR(__xludf.DUMMYFUNCTION("COUNTIFS(IMPORTRANGE('Survey Progress'!$B$33, ""data!B2:B800""), ""=""&$A4, IMPORTRANGE('Survey Progress'!$B$33, ""data!O2:O800""), ""*""&Q$2&""*"")"),0.0) -> 0 | R4: =IFERROR(__xludf.DUMMYFUNCTION("COUNTIFS(IMPORTRANGE('Survey Progress'!$B$33, ""data!B2:B800""), ""=""&$A4, IMPORTRANGE('Survey Progress'!$B$33, ""data!O2:O800""), ""*""&R$2&""*"")"),0.0) -> 0 | S4: =IFERROR(__xludf.DUMMYFUNCTION("COUNTIFS(IMPORTRANGE('Survey Progress'!$B$33, ""data!B2:B800""), ""=""&$A4, IMPORTRANGE('Survey Progress'!$B$33, ""data!O2:O800""), ""*""&S$2&""*"")"),0.0) -> 0 | T4: =IFERROR(__xludf.DUMMYFUNCTION("COUNTIFS(IMPORTRANGE('Survey Progress'!$B$33, ""data!B2:B800""), ""=""&$A4, IMPORTRANGE('Survey Progress'!$B$33, ""data!O2:O800""), ""*""&T$2&""*"")"),0.0) -> 0
A5: Imarane Issa Rabo | B5: Woman | C5: =IFERROR(__xludf.DUMMYFUNCTION("COUNTIFS(IMPORTRANGE('Survey Progress'!$B$34, ""data!B2:B800""), ""=""&$A5, IMPORTRANGE('Survey Progress'!$B$34, ""data!O2:O800""), ""*""&C$2&""*"")"),0.0) -> 0 | D5: =IFERROR(__xludf.DUMMYFUNCTION("COUNTIFS(IMPORTRANGE('Survey Progress'!$B$34, ""data!B2:B800""), ""=""&$A5, IMPORTRANGE('Survey Progress'!$B$34, ""data!O2:O800""), ""*""&D$2&""*"")"),0.0) -> 0 | E5: =IFERROR(__xludf.DUMMYFUNCTION("COUNTIFS(IMPORTRANGE('Survey Progress'!$B$34, ""data!B2:B800""), ""=""&$A5, IMPORTRANGE('Survey Progress'!$B$34, ""data!O2:O800""), ""*""&E$2&""*"")"),0.0) -> 0 | F5: =IFERROR(__xludf.DUMMYFUNCTION("COUNTIFS(IMPORTRANGE('Survey Progress'!$B$34, ""data!B2:B800""), ""=""&$A5, IMPORTRANGE('Survey Progress'!$B$34, ""data!O2:O800""), ""*""&F$2&""*"")"),0.0) -> 0 | G5: =IFERROR(__xludf.DUMMYFUNCTION("COUNTIFS(IMPORTRANGE('Survey Progress'!$B$34, ""data!B2:B800""), ""=""&$A5, IMPORTRANGE('Survey Progress'!$B$34, ""data!O2:O800""), ""*""&G$2&""*"")"),0.0) -> 0 | H5: =IFERROR(__xludf.DUMMYFUNCTION("COUNTIFS(IMPORTRANGE('Survey Progress'!$B$34, ""data!B2:B800""), ""=""&$A5, IMPORTRANGE('Survey Progress'!$B$34, ""data!O2:O800""), ""*""&H$2&""*"")"),0.0) -> 0 | I5: =IFERROR(__xludf.DUMMYFUNCTION("COUNTIFS(IMPORTRANGE('Survey Progress'!$B$34, ""data!B2:B800""), ""=""&$A5, IMPORTRANGE('Survey Progress'!$B$34, ""data!O2:O800""), ""*""&I$2&""*"")"),0.0) -> 0 | J5: =IFERROR(__xludf.DUMMYFUNCTION("COUNTIFS(IMPORTRANGE('Survey Progress'!$B$34, ""data!B2:B800""), ""=""&$A5, IMPORTRANGE('Survey Progress'!$B$34, ""data!O2:O800""), ""*""&J$2&""*"")"),0.0) -> 0 | K5: =IFERROR(__xludf.DUMMYFUNCTION("COUNTIFS(IMPORTRANGE('Survey Progress'!$B$34, ""data!B2:B800""), ""=""&$A5, IMPORTRANGE('Survey Progress'!$B$34, ""data!O2:O800""), ""*""&K$2&""*"")"),0.0) -> 0 | L5: =IFERROR(__xludf.DUMMYFUNCTION("COUNTIFS(IMPORTRANGE('Survey Progress'!$B$34, ""data!B2:B800""), ""=""&$A5, IMPORTRANGE('Survey Progress'!$B$34, ""data!O2:O800""), ""*""&L$2&""*"")"),0.0) -> 0 | M5: =IFERROR(__xludf.DUMMYFUNCTION("COUNTIFS(IMPORTRANGE('Survey Progress'!$B$34, ""data!B2:B800""), ""=""&$A5, IMPORTRANGE('Survey Progress'!$B$34, ""data!O2:O800""), ""*""&M$2&""*"")"),0.0) -> 0 | N5: =IFERROR(__xludf.DUMMYFUNCTION("COUNTIFS(IMPORTRANGE('Survey Progress'!$B$34, ""data!B2:B800""), ""=""&$A5, IMPORTRANGE('Survey Progress'!$B$34, ""data!O2:O800""), ""*""&N$2&""*"")"),0.0) -> 0 | O5: =IFERROR(__xludf.DUMMYFUNCTION("COUNTIFS(IMPORTRANGE('Survey Progress'!$B$34, ""data!B2:B800""), ""=""&$A5, IMPORTRANGE('Survey Progress'!$B$34, ""data!O2:O800""), ""*""&O$2&""*"")"),0.0) -> 0 | P5: =IFERROR(__xludf.DUMMYFUNCTION("COUNTIFS(IMPORTRANGE('Survey Progress'!$B$34, ""data!B2:B800""), ""=""&$A5, IMPORTRANGE('Survey Progress'!$B$34, ""data!O2:O800""), ""*""&P$2&""*"")"),0.0) -> 0 | Q5: =IFERROR(__xludf.DUMMYFUNCTION("COUNTIFS(IMPORTRANGE('Survey Progress'!$B$34, ""data!B2:B800""), ""=""&$A5, IMPORTRANGE('Survey Progress'!$B$34, ""data!O2:O800""), ""*""&Q$2&""*"")"),0.0) -> 0 | R5: =IFERROR(__xludf.DUMMYFUNCTION("COUNTIFS(IMPORTRANGE('Survey Progress'!$B$34, ""data!B2:B800""), ""=""&$A5, IMPORTRANGE('Survey Progress'!$B$34, ""data!O2:O800""), ""*""&R$2&""*"")"),0.0) -> 0 | S5: =IFERROR(__xludf.DUMMYFUNCTION("COUNTIFS(IMPORTRANGE('Survey Progress'!$B$34, ""data!B2:B800""), ""=""&$A5, IMPORTRANGE('Survey Progress'!$B$34, ""data!O2:O800""), ""*""&S$2&""*"")"),0.0) -> 0 | T5: =IFERROR(__xludf.DUMMYFUNCTION("COUNTIFS(IMPORTRANGE('Survey Progress'!$B$34, ""data!B2:B800""), ""=""&$A5, IMPORTRANGE('Survey Progress'!$B$34, ""data!O2:O800""), ""*""&T$2&""*"")"),0.0) -> 0
A6: Gado Abdoul Aziz | B6: Screening & HHH | C6: =IFERROR(__xludf.DUMMYFUNCTION("COUNTIFS(IMPORTRANGE('Survey Progress'!$B$32, ""data!$B$2:$B$800""), ""=""&$A6, IMPORTRANGE('Survey Progress'!$B$32, ""data!$S$2:$S$800""), ""*""&C$2&""*"")"),0.0) -> 0 | D6: =IFERROR(__xludf.DUMMYFUNCTION("COUNTIFS(IMPORTRANGE('Survey Progress'!$B$32, ""data!$B$2:$B$800""), ""=""&$A6, IMPORTRANGE('Survey Progress'!$B$32, ""data!$S$2:$S$800""), ""*""&D$2&""*"")"),0.0) -> 0 | E6: =IFERROR(__xludf.DUMMYFUNCTION("COUNTIFS(IMPORTRANGE('Survey Progress'!$B$32, ""data!$B$2:$B$800""), ""=""&$A6, IMPORTRANGE('Survey Progress'!$B$32, ""data!$S$2:$S$800""), ""*""&E$2&""*"")"),0.0) -> 0 | F6: =IFERROR(__xludf.DUMMYFUNCTION("COUNTIFS(IMPORTRANGE('Survey Progress'!$B$32, ""data!$B$2:$B$800""), ""=""&$A6, IMPORTRANGE('Survey Progress'!$B$32, ""data!$S$2:$S$800""), ""*""&F$2&""*"")"),0.0) -> 0 | G6: =IFERROR(__xludf.DUMMYFUNCTION("COUNTIFS(IMPORTRANGE('Survey Progress'!$B$32, ""data!$B$2:$B$800""), ""=""&$A6, IMPORTRANGE('Survey Progress'!$B$32, ""data!$S$2:$S$800""), ""*""&G$2&""*"")"),0.0) -> 0 | H6: =IFERROR(__xludf.DUMMYFUNCTION("COUNTIFS(IMPORTRANGE('Survey Progress'!$B$32, ""data!$B$2:$B$800""), ""=""&$A6, IMPORTRANGE('Survey Progress'!$B$32, ""data!$S$2:$S$800""), ""*""&H$2&""*"")"),0.0) -> 0 | I6: =IFERROR(__xludf.DUMMYFUNCTION("COUNTIFS(IMPORTRANGE('Survey Progress'!$B$32, ""data!$B$2:$B$800""), ""=""&$A6, IMPORTRANGE('Survey Progress'!$B$32, ""data!$S$2:$S$800""), ""*""&I$2&""*"")"),0.0) -> 0 | J6: =IFERROR(__xludf.DUMMYFUNCTION("COUNTIFS(IMPORTRANGE('Survey Progress'!$B$32, ""data!$B$2:$B$800""), ""=""&$A6, IMPORTRANGE('Survey Progress'!$B$32, ""data!$S$2:$S$800""), ""*""&J$2&""*"")"),0.0) -> 0 | K6: =IFERROR(__xludf.DUMMYFUNCTION("COUNTIFS(IMPORTRANGE('Survey Progress'!$B$32, ""data!$B$2:$B$800""), ""=""&$A6, IMPORTRANGE('Survey Progress'!$B$32, ""data!$S$2:$S$800""), ""*""&K$2&""*"")"),0.0) -> 0 | L6: =IFERROR(__xludf.DUMMYFUNCTION("COUNTIFS(IMPORTRANGE('Survey Progress'!$B$32, ""data!$B$2:$B$800""), ""=""&$A6, IMPORTRANGE('Survey Progress'!$B$32, ""data!$S$2:$S$800""), ""*""&L$2&""*"")"),0.0) -> 0 | M6: =IFERROR(__xludf.DUMMYFUNCTION("COUNTIFS(IMPORTRANGE('Survey Progress'!$B$32, ""data!$B$2:$B$800""), ""=""&$A6, IMPORTRANGE('Survey Progress'!$B$32, ""data!$S$2:$S$800""), ""*""&M$2&""*"")"),0.0) -> 0 | N6: =IFERROR(__xludf.DUMMYFUNCTION("COUNTIFS(IMPORTRANGE('Survey Progress'!$B$32, ""data!$B$2:$B$800""), ""=""&$A6, IMPORTRANGE('Survey Progress'!$B$32, ""data!$S$2:$S$800""), ""*""&N$2&""*"")"),0.0) -> 0 | O6: =IFERROR(__xludf.DUMMYFUNCTION("COUNTIFS(IMPORTRANGE('Survey Progress'!$B$32, ""data!$B$2:$B$800""), ""=""&$A6, IMPORTRANGE('Survey Progress'!$B$32, ""data!$S$2:$S$800""), ""*""&O$2&""*"")"),0.0) -> 0 | P6: =IFERROR(__xludf.DUMMYFUNCTION("COUNTIFS(IMPORTRANGE('Survey Progress'!$B$32, ""data!$B$2:$B$800""), ""=""&$A6, IMPORTRANGE('Survey Progress'!$B$32, ""data!$S$2:$S$800""), ""*""&P$2&""*"")"),0.0) -> 0 | Q6: =IFERROR(__xludf.DUMMYFUNCTION("COUNTIFS(IMPORTRANGE('Survey Progress'!$B$32, ""data!$B$2:$B$800""), ""=""&$A6, IMPORTRANGE('Survey Progress'!$B$32, ""data!$S$2:$S$800""), ""*""&Q$2&""*"")"),0.0) -> 0 | R6: =IFERROR(__xludf.DUMMYFUNCTION("COUNTIFS(IMPORTRANGE('Survey Progress'!$B$32, ""data!$B$2:$B$800""), ""=""&$A6, IMPORTRANGE('Survey Progress'!$B$32, ""data!$S$2:$S$800""), ""*""&R$2&""*"")"),0.0) -> 0 | S6: =IFERROR(__xludf.DUMMYFUNCTION("COUNTIFS(IMPORTRANGE('Survey Progress'!$B$32, ""data!$B$2:$B$800""), ""=""&$A6, IMPORTRANGE('Survey Progress'!$B$32, ""data!$S$2:$S$800""), ""*""&S$2&""*"")"),0.0) -> 0 | T6: =IFERROR(__xludf.DUMMYFUNCTION("COUNTIFS(IMPORTRANGE('Survey Progress'!$B$32, ""data!$B$2:$B$800""), ""=""&$A6, IMPORTRANGE('Survey Progress'!$B$32, ""data!$S$2:$S$800""), ""*""&T$2&""*"")"),0.0) -> 0
